<sdf version='1.6'>
  <world name='track_levine'>
    <gui fullscreen='0'>
      <camera name='camera'>
        <pose frame=''>-2.41002 2.59549 33.1688 0 1.57 0</pose>
        <view_controller>orbit</view_controller>
        <projection_type>perspective</projection_type>
      </camera>
    </gui>
    <scene>
      <ambient>0.5 0.5 0.5 1</ambient>
      <shadows>0</shadows>
      <background>0.7 0.7 0.7 1</background>
    </scene>
    <light name='sun' type='directional'>
      <cast_shadows>1</cast_shadows>
      <pose frame=''>0 0 10 0 -0 0</pose>
      <diffuse>0.8 0.8 0.8 1</diffuse>
      <specular>0.1 0.1 0.1 1</specular>
      <attenuation>
        <range>1000</range>
        <constant>0.9</constant>
        <linear>0.01</linear>
        <quadratic>0.001</quadratic>
      </attenuation>
      <direction>-0.5 0.5 -1</direction>
    </light>
    <light name='Light 1' type='point'>
      <pose frame=''>0 0 15 0 -0 0</pose>
      <diffuse>0.9 0.9 0.9 1</diffuse>
      <specular>0.1 0.1 0.1 1</specular>
      <attenuation>
        <constant>0.5</constant>
        <linear>0.01</linear>
        <quadratic>0</quadratic>
        <range>50</range>
      </attenuation>
      <direction>0 0 -1</direction>
      <cast_shadows>0</cast_shadows>
    </light>
    <model name='ground_plane'>
      <static>1</static>
      <link name='link'>
        <collision name='collision'>
          <geometry>
            <plane>
              <normal>0 0 1</normal>
              <size>150 150</size>
            </plane>
          </geometry>
          <surface>
            <friction>
              <ode>
                <mu>100</mu>
                <mu2>50</mu2>
              </ode>
              <torsional>
                <ode/>
              </torsional>
            </friction>
            <contact>
              <ode/>
            </contact>
            <bounce/>
          </surface>
          <max_contacts>10</max_contacts>
        </collision>
        <visual name='visual'>
          <cast_shadows>0</cast_shadows>
          <geometry>
            <plane>
              <normal>0 0 1</normal>
              <size>150 150</size>
            </plane>
          </geometry>
          <material>
            <script>
              <uri>file://media/materials/scripts/gazebo.material</uri>
              <name>Gazebo/Grey</name>
            </script>
          </material>
        </visual>
        <self_collide>0</self_collide>
        <kinematic>0</kinematic>
        <gravity>1</gravity>
      </link>
    </model>
    <model name='levine_track'>
      <link name='link'>
        <collision name='collision'>
          <geometry>
            <mesh>
              <uri>model://racecar_description/meshes/levine_track.dae</uri>
              <scale>1 1 1</scale>
            </mesh>
          </geometry>
          <max_contacts>10</max_contacts>
          <surface>
            <contact>
              <ode/>
            </contact>
            <bounce/>
            <friction>
              <torsional>
                <ode/>
              </torsional>
              <ode/>
            </friction>
          </surface>
        </collision>
        <visual name='visual'>
          <geometry>
            <mesh>
              <uri>model://racecar_description/meshes/levine_track.dae</uri>
              <scale>1 1 1</scale>
            </mesh>
          </geometry>
        </visual>
        <self_collide>0</self_collide>
        <kinematic>0</kinematic>
        <gravity>1</gravity>
      </link>
      <static>1</static>
      <pose frame=''>-1.3 0 -0.1 0 -0 0</pose>
    </model>
    <gravity>0 0 -9.8</gravity>
    <magnetic_field>6e-06 2.3e-05 -4.2e-05</magnetic_field>
    <atmosphere type='adiabatic'/>
    <physics name='default_physics' default='0' type='ode'>
      <max_step_size>0.001</max_step_size>
      <real_time_factor>1</real_time_factor>
      <real_time_update_rate>1000</real_time_update_rate>
    </physics>
    <spherical_coordinates>
      <surface_model>EARTH_WGS84</surface_model>
      <latitude_deg>0</latitude_deg>
      <longitude_deg>0</longitude_deg>
      <elevation>0</elevation>
      <heading_deg>0</heading_deg>
    </spherical_coordinates>
    <model name='racecar'>
      <link name='base_link'>
        <pose frame=''>0 0 0 0 -0 0</pose>
        <inertial>
          <pose frame=''>0.149206 0 0.050963 0 -0 0</pose>
          <mass>10.13</mass>
          <inertia>
            <ixx>0.011338</ixx>
            <ixy>0</ixy>
            <ixz>-0.00112928</ixz>
            <iyy>0.0529054</iyy>
            <iyz>0</iyz>
            <izz>0.0604246</izz>
          </inertia>
        </inertial>
        <collision name='base_link_fixed_joint_lump__laser_collision'>
          <pose frame=''>0.265 0 0.125 0 -0 0</pose>
          <geometry>
            <box>
              <size>0.1 0.1 0.1</size>
            </box>
          </geometry>
          <surface>
            <contact>
              <ode/>
            </contact>
            <friction>
              <ode/>
              <torsional>
                <ode/>
              </torsional>
            </friction>
            <bounce/>
          </surface>
          <max_contacts>10</max_contacts>
        </collision>
        <collision name='base_link_fixed_joint_lump__zed_camera_link_collision_1'>
          <pose frame=''>0.39 0 0.09 0 -0 0</pose>
          <geometry>
            <box>
              <size>0.033 0.175 0.03</size>
            </box>
          </geometry>
          <max_contacts>10</max_contacts>
          <surface>
            <contact>
              <ode/>
            </contact>
            <bounce/>
            <friction>
              <torsional>
                <ode/>
              </torsional>
              <ode/>
            </friction>
          </surface>
        </collision>
        <visual name='base_link_fixed_joint_lump__chassis_visual'>
          <pose frame=''>0 0 0.05 0 -0 0</pose>
          <geometry>
            <mesh>
              <scale>1 1 1</scale>
              <uri>/home/nikhil/ESE680/src/f110-fall2018-skeletons/simulator/racecar-simulator/racecar_description/meshes/chassis.STL</uri>
            </mesh>
          </geometry>
          <material>
            <script>
              <name>Gazebo/Red</name>
              <uri>file://media/materials/scripts/gazebo.material</uri>
            </script>
          </material>
        </visual>
        <visual name='base_link_fixed_joint_lump__laser_visual_1'>
          <pose frame=''>0.265 0 0.125 0 -0 0</pose>
          <geometry>
            <mesh>
              <scale>1 1 1</scale>
              <uri>/home/nikhil/ESE680/src/f110-fall2018-skeletons/simulator/racecar-simulator/racecar_description/meshes/hokuyo.dae</uri>
            </mesh>
          </geometry>
          <material>
            <script>
              <name>Gazebo/Grey</name>
              <uri>file://media/materials/scripts/gazebo.material</uri>
            </script>
          </material>
        </visual>
        <visual name='base_link_fixed_joint_lump__zed_camera_link_visual_2'>
          <pose frame=''>0.39 0 0.09 0 -0 0</pose>
          <geometry>
            <box>
              <size>0.033 0.175 0.03</size>
            </box>
          </geometry>
        </visual>
        <velocity_decay/>
        <velocity_decay/>
        <sensor name='hokuyo_sensor' type='ray'>
          <visualize>1</visualize>
          <update_rate>40</update_rate>
          <ray>
            <scan>
              <horizontal>
                <samples>1081</samples>
                <resolution>1</resolution>
                <min_angle>-2.35619</min_angle>
                <max_angle>2.35619</max_angle>
              </horizontal>
              <vertical>
                <samples>1</samples>
                <min_angle>0</min_angle>
                <max_angle>0</max_angle>
              </vertical>
            </scan>
            <range>
              <min>0.1</min>
              <max>10</max>
              <resolution>0.01</resolution>
            </range>
            <noise>
              <mean>0</mean>
              <stddev>0.01</stddev>
              <type>gaussian</type>
            </noise>
          </ray>
          <plugin name='gazebo_ros_hokuyo_controller' filename='libgazebo_ros_laser.so'>
            <topicName>/scan</topicName>
            <frameName>laser</frameName>
            <robotNamespace>/</robotNamespace>
          </plugin>
          <pose frame=''>0.265 0 0.125 0 -0 0</pose>
        </sensor>
        <gravity>1</gravity>
        <velocity_decay/>
        <self_collide>0</self_collide>
        <sensor name='zed_camera_left_sensor' type='camera'>
          <update_rate>30</update_rate>
          <camera name='zed_camera_left_camera'>
            <horizontal_fov>0.870922</horizontal_fov>
            <image>
              <width>640</width>
              <height>480</height>
              <format>B8G8R8</format>
            </image>
            <clip>
              <near>0.02</near>
              <far>300</far>
            </clip>
            <noise>
              <type>gaussian</type>
              <mean>0</mean>
              <stddev>0.007</stddev>
            </noise>
          </camera>
          <plugin name='camera_controller' filename='libgazebo_ros_camera.so'>
            <alwaysOn>true</alwaysOn>
            <updateRate>30.0</updateRate>
            <cameraName>/camera/zed</cameraName>
            <imageTopicName>rgb/image_rect_color</imageTopicName>
            <cameraInfoTopicName>rgb/camera_info</cameraInfoTopicName>
            <frameName>camera_link</frameName>
            <hackBaseline>0</hackBaseline>
            <distortionK1>0.0</distortionK1>
            <distortionK2>0.0</distortionK2>
            <distortionK3>0.0</distortionK3>
            <distortionT1>0.0</distortionT1>
            <distortionT2>0.0</distortionT2>
            <robotNamespace>/</robotNamespace>
          </plugin>
          <pose frame=''>0.39 0.06 0.09 0 -0 0</pose>
        </sensor>
        <kinematic>0</kinematic>
      </link>
      <link name='left_rear_wheel'>
        <pose frame=''>0 0.1 0.05 1.5708 -0 0</pose>
        <inertial>
          <pose frame=''>0 0 -0.0225 0 -0 0</pose>
          <mass>0.34055</mass>
          <inertia>
            <ixx>0.00026046</ixx>
            <ixy>0</ixy>
            <ixz>0</ixz>
            <iyy>0.00026046</iyy>
            <iyz>0</iyz>
            <izz>0.00041226</izz>
          </inertia>
        </inertial>
        <collision name='left_rear_wheel_collision'>
          <pose frame=''>0 0 -0.0225 0 -0 0</pose>
          <geometry>
            <cylinder>
              <length>0.045</length>
              <radius>0.05</radius>
            </cylinder>
          </geometry>
          <surface>
            <contact>
              <ode>
                <kp>1e+07</kp>
                <kd>1</kd>
              </ode>
            </contact>
            <friction>
              <ode>
                <mu>2</mu>
                <mu2>2</mu2>
                <fdir1>1 0 0</fdir1>
              </ode>
              <torsional>
                <ode/>
              </torsional>
            </friction>
            <bounce/>
          </surface>
          <max_contacts>10</max_contacts>
        </collision>
        <visual name='left_rear_wheel_visual'>
          <pose frame=''>0 0 0 0 -0 0</pose>
          <geometry>
            <mesh>
              <scale>1 1 1</scale>
              <uri>/home/nikhil/ESE680/src/f110-fall2018-skeletons/simulator/racecar-simulator/racecar_description/meshes/left_rear_wheel.STL</uri>
            </mesh>
          </geometry>
          <material>
            <script>
              <name>Gazebo/Black</name>
              <uri>file://media/materials/scripts/gazebo.material</uri>
            </script>
          </material>
        </visual>
        <gravity>1</gravity>
        <velocity_decay/>
        <self_collide>0</self_collide>
        <kinematic>0</kinematic>
      </link>
      <joint name='left_rear_wheel_joint' type='revolute'>
        <child>left_rear_wheel</child>
        <parent>base_link</parent>
        <axis>
          <xyz>0 1 4e-06</xyz>
          <limit>
            <lower>-1e+16</lower>
            <upper>1e+16</upper>
          </limit>
          <dynamics>
            <spring_reference>0</spring_reference>
            <spring_stiffness>0</spring_stiffness>
          </dynamics>
          <use_parent_model_frame>1</use_parent_model_frame>
        </axis>
      </joint>
      <link name='left_steering_hinge'>
        <pose frame=''>0.325 0.1 0.05 3.14159 1.57079 3.14159</pose>
        <inertial>
          <pose frame=''>0 0 0 0 -0 0</pose>
          <mass>0.1</mass>
          <inertia>
            <ixx>4e-06</ixx>
            <ixy>0</ixy>
            <ixz>0</ixz>
            <iyy>4e-06</iyy>
            <iyz>0</iyz>
            <izz>4e-06</izz>
          </inertia>
        </inertial>
        <visual name='left_steering_hinge_visual'>
          <pose frame=''>0 0 0 0 -0 0</pose>
          <geometry>
            <mesh>
              <scale>1 1 1</scale>
              <uri>/home/nikhil/ESE680/src/f110-fall2018-skeletons/simulator/racecar-simulator/racecar_description/meshes/left_steering_hinge.STL</uri>
            </mesh>
          </geometry>
        </visual>
        <self_collide>0</self_collide>
        <kinematic>0</kinematic>
        <gravity>1</gravity>
      </link>
      <joint name='left_steering_hinge_joint' type='revolute'>
        <child>left_steering_hinge</child>
        <parent>base_link</parent>
        <axis>
          <xyz>4e-06 0 1</xyz>
          <limit>
            <lower>-1</lower>
            <upper>1</upper>
            <effort>10</effort>
            <velocity>1000</velocity>
          </limit>
          <dynamics>
            <spring_reference>0</spring_reference>
            <spring_stiffness>0</spring_stiffness>
          </dynamics>
          <use_parent_model_frame>1</use_parent_model_frame>
        </axis>
      </joint>
      <link name='left_front_wheel'>
        <pose frame=''>0.325 0.1 0.05 -1.57079 1.57079 -3.14159</pose>
        <inertial>
          <pose frame=''>0 0 -0.0225 0 -0 0</pose>
          <mass>0.34055</mass>
          <inertia>
            <ixx>0.00026046</ixx>
            <ixy>0</ixy>
            <ixz>0</ixz>
            <iyy>0.00026046</iyy>
            <iyz>0</iyz>
            <izz>0.00041226</izz>
          </inertia>
        </inertial>
        <collision name='left_front_wheel_collision'>
          <pose frame=''>0 0 -0.0225 0 -0 0</pose>
          <geometry>
            <cylinder>
              <length>0.045</length>
              <radius>0.05</radius>
            </cylinder>
          </geometry>
          <surface>
            <contact>
              <ode>
                <kp>1e+07</kp>
                <kd>1</kd>
              </ode>
            </contact>
            <friction>
              <ode>
                <mu>2</mu>
                <mu2>2</mu2>
                <fdir1>0 0 1</fdir1>
              </ode>
              <torsional>
                <ode/>
              </torsional>
            </friction>
            <bounce/>
          </surface>
          <max_contacts>10</max_contacts>
        </collision>
        <visual name='left_front_wheel_visual'>
          <pose frame=''>0 0 0 0 -0 0</pose>
          <geometry>
            <mesh>
              <scale>1 1 1</scale>
              <uri>/home/nikhil/ESE680/src/f110-fall2018-skeletons/simulator/racecar-simulator/racecar_description/meshes/left_front_wheel.STL</uri>
            </mesh>
          </geometry>
          <material>
            <script>
              <name>Gazebo/Black</name>
              <uri>file://media/materials/scripts/gazebo.material</uri>
            </script>
          </material>
        </visual>
        <gravity>1</gravity>
        <velocity_decay/>
        <self_collide>0</self_collide>
        <kinematic>0</kinematic>
      </link>
      <joint name='left_front_wheel_joint' type='revolute'>
        <child>left_front_wheel</child>
        <parent>left_steering_hinge</parent>
        <axis>
          <xyz>4e-06 1 0</xyz>
          <limit>
            <lower>-1e+16</lower>
            <upper>1e+16</upper>
          </limit>
          <dynamics>
            <spring_reference>0</spring_reference>
            <spring_stiffness>0</spring_stiffness>
          </dynamics>
          <use_parent_model_frame>1</use_parent_model_frame>
        </axis>
      </joint>
      <link name='right_rear_wheel'>
        <pose frame=''>0 -0.1 0.05 1.5708 -0 0</pose>
        <inertial>
          <pose frame=''>0 0 0.0225 0 -0 0</pose>
          <mass>0.34055</mass>
          <inertia>
            <ixx>0.00026046</ixx>
            <ixy>0</ixy>
            <ixz>0</ixz>
            <iyy>0.00026046</iyy>
            <iyz>0</iyz>
            <izz>0.00041226</izz>
          </inertia>
        </inertial>
        <collision name='right_rear_wheel_collision'>
          <pose frame=''>0 0 0.0225 0 -0 0</pose>
          <geometry>
            <cylinder>
              <length>0.045</length>
              <radius>0.05</radius>
            </cylinder>
          </geometry>
          <surface>
            <contact>
              <ode>
                <kp>1e+07</kp>
                <kd>1</kd>
              </ode>
            </contact>
            <friction>
              <ode>
                <mu>2</mu>
                <mu2>2</mu2>
                <fdir1>1 0 0</fdir1>
              </ode>
              <torsional>
                <ode/>
              </torsional>
            </friction>
            <bounce/>
          </surface>
          <max_contacts>10</max_contacts>
        </collision>
        <visual name='right_rear_wheel_visual'>
          <pose frame=''>0 0 0 0 -0 0</pose>
          <geometry>
            <mesh>
              <scale>1 1 1</scale>
              <uri>/home/nikhil/ESE680/src/f110-fall2018-skeletons/simulator/racecar-simulator/racecar_description/meshes/right_rear_wheel.STL</uri>
            </mesh>
          </geometry>
          <material>
            <script>
              <name>Gazebo/Black</name>
              <uri>file://media/materials/scripts/gazebo.material</uri>
            </script>
          </material>
        </visual>
        <gravity>1</gravity>
        <velocity_decay/>
        <self_collide>0</self_collide>
        <kinematic>0</kinematic>
      </link>
      <joint name='right_rear_wheel_joint' type='revolute'>
        <child>right_rear_wheel</child>
        <parent>base_link</parent>
        <axis>
          <xyz>0 1 4e-06</xyz>
          <limit>
            <lower>-1e+16</lower>
            <upper>1e+16</upper>
          </limit>
          <dynamics>
            <spring_reference>0</spring_reference>
            <spring_stiffness>0</spring_stiffness>
          </dynamics>
          <use_parent_model_frame>1</use_parent_model_frame>
        </axis>
      </joint>
      <link name='right_steering_hinge'>
        <pose frame=''>0.325 -0.1 0.05 3.14159 1.57079 3.14159</pose>
        <inertial>
          <pose frame=''>0 0 0 0 -0 0</pose>
          <mass>0.1</mass>
          <inertia>
            <ixx>4e-06</ixx>
            <ixy>0</ixy>
            <ixz>0</ixz>
            <iyy>4e-06</iyy>
            <iyz>0</iyz>
            <izz>4e-06</izz>
          </inertia>
        </inertial>
        <visual name='right_steering_hinge_visual'>
          <pose frame=''>0 0 0 0 -0 0</pose>
          <geometry>
            <mesh>
              <scale>1 1 1</scale>
              <uri>/home/nikhil/ESE680/src/f110-fall2018-skeletons/simulator/racecar-simulator/racecar_description/meshes/right_steering_hinge.STL</uri>
            </mesh>
          </geometry>
        </visual>
        <self_collide>0</self_collide>
        <kinematic>0</kinematic>
        <gravity>1</gravity>
      </link>
      <joint name='right_steering_hinge_joint' type='revolute'>
        <child>right_steering_hinge</child>
        <parent>base_link</parent>
        <axis>
          <xyz>4e-06 0 1</xyz>
          <limit>
            <lower>-1e+16</lower>
            <upper>1e+16</upper>
          </limit>
          <dynamics>
            <spring_reference>0</spring_reference>
            <spring_stiffness>0</spring_stiffness>
          </dynamics>
          <use_parent_model_frame>1</use_parent_model_frame>
        </axis>
      </joint>
      <link name='right_front_wheel'>
        <pose frame=''>0.325 -0.1 0.05 -1.57079 1.57079 -3.14159</pose>
        <inertial>
          <pose frame=''>0 0 0.0225 0 -0 0</pose>
          <mass>0.34055</mass>
          <inertia>
            <ixx>0.00026046</ixx>
            <ixy>0</ixy>
            <ixz>0</ixz>
            <iyy>0.00026046</iyy>
            <iyz>0</iyz>
            <izz>0.00041226</izz>
          </inertia>
        </inertial>
        <collision name='right_front_wheel_collision'>
          <pose frame=''>0 0 0.0225 0 -0 0</pose>
          <geometry>
            <cylinder>
              <length>0.045</length>
              <radius>0.05</radius>
            </cylinder>
          </geometry>
          <surface>
            <contact>
              <ode>
                <kp>1e+07</kp>
                <kd>1</kd>
              </ode>
            </contact>
            <friction>
              <ode>
                <mu>2</mu>
                <mu2>2</mu2>
                <fdir1>0 0 1</fdir1>
              </ode>
              <torsional>
                <ode/>
              </torsional>
            </friction>
            <bounce/>
          </surface>
          <max_contacts>10</max_contacts>
        </collision>
        <visual name='right_front_wheel_visual'>
          <pose frame=''>0 0 0 0 -0 0</pose>
          <geometry>
            <mesh>
              <scale>1 1 1</scale>
              <uri>/home/nikhil/ESE680/src/f110-fall2018-skeletons/simulator/racecar-simulator/racecar_description/meshes/right_front_wheel.STL</uri>
            </mesh>
          </geometry>
          <material>
            <script>
              <name>Gazebo/Black</name>
              <uri>file://media/materials/scripts/gazebo.material</uri>
            </script>
          </material>
        </visual>
        <gravity>1</gravity>
        <velocity_decay/>
        <self_collide>0</self_collide>
        <kinematic>0</kinematic>
      </link>
      <joint name='right_front_wheel_joint' type='revolute'>
        <child>right_front_wheel</child>
        <parent>right_steering_hinge</parent>
        <axis>
          <xyz>4e-06 1 0</xyz>
          <limit>
            <lower>-1e+16</lower>
            <upper>1e+16</upper>
          </limit>
          <dynamics>
            <spring_reference>0</spring_reference>
            <spring_stiffness>0</spring_stiffness>
          </dynamics>
          <use_parent_model_frame>1</use_parent_model_frame>
        </axis>
      </joint>
      <static>0</static>
      <plugin name='gazebo_ros_control' filename='libgazebo_ros_control.so'>
        <robotNamespace>/racecar</robotNamespace>
        <robotSimType>gazebo_ros_control/DefaultRobotHWSim</robotSimType>
      </plugin>
      <pose frame=''>0 0 0.05 0 -0 0</pose>
    </model>
    <state world_name='track_levine'>
      <sim_time>128 289000000</sim_time>
      <real_time>41 565430030</real_time>
      <wall_time>1543786009 835225604</wall_time>
      <iterations>34946</iterations>
      <model name='ground_plane'>
        <pose frame=''>0 0 0 0 -0 0</pose>
        <scale>1 1 1</scale>
        <link name='link'>
          <pose frame=''>0 0 0 0 -0 0</pose>
          <velocity>0 0 0 0 -0 0</velocity>
          <acceleration>0 0 0 0 -0 0</acceleration>
          <wrench>0 0 0 0 -0 0</wrench>
        </link>
      </model>
      <model name='levine_track'>
        <pose frame=''>-2.18 0 -0.1 0 -0 0</pose>
        <scale>1 1 1</scale>
        <link name='link'>
          <pose frame=''>-2.18 0 -0.1 0 -0 0</pose>
          <velocity>0 0 0 0 -0 0</velocity>
          <acceleration>0 0 0 0 -0 0</acceleration>
          <wrench>0 0 0 0 -0 0</wrench>
        </link>
      </model>
      <model name='racecar'>
        <pose frame=''>-8e-06 -3e-06 -2e-06 2e-06 6e-06 -3e-06</pose>
        <scale>1 1 1</scale>
        <link name='base_link'>
          <pose frame=''>-8e-06 -3e-06 -2e-06 2e-06 6e-06 -3e-06</pose>
          <velocity>1e-06 -1e-06 1.2e-05 3e-06 -1.2e-05 7e-06</velocity>
          <acceleration>0 -1e-06 0 1e-06 1e-06 -7e-06</acceleration>
          <wrench>0 -8e-06 -2e-06 0 -0 0</wrench>
        </link>
        <link name='left_front_wheel'>
          <pose frame=''>0.324993 0.099996 0.049997 1.60495 1.56907 0.034105</pose>
          <velocity>-1e-06 7e-06 1.5e-05 -0.00015 -3.7e-05 4.8e-05</velocity>
          <acceleration>1e-06 -2e-06 0 3.6e-05 0.011091 -5e-06</acceleration>
          <wrench>0 -1e-06 0 0 -0 0</wrench>
        </link>
        <link name='left_rear_wheel'>
          <pose frame=''>-7e-06 0.099997 0.049999 1.57079 -0.000136 -3e-06</pose>
          <velocity>-1e-06 -1e-06 1.3e-05 1e-05 -1.5e-05 1e-06</velocity>
          <acceleration>1e-06 0 0 -4e-06 0.003366 -2e-06</acceleration>
          <wrench>0 0 0 0 -0 0</wrench>
        </link>
        <link name='left_steering_hinge'>
          <pose frame=''>0.324993 0.099996 0.049997 1.69786 1.5707 1.69782</pose>
          <velocity>0 6e-06 1.7e-05 -0.000325 -1.2e-05 5.4e-05</velocity>
          <acceleration>1e-06 -2e-06 -1e-06 3.8e-05 1e-06 -3e-06</acceleration>
          <wrench>0 0 0 0 -0 0</wrench>
        </link>
        <link name='right_front_wheel'>
          <pose frame=''>0.324992 -0.100004 0.049997 -1.37844 1.57051 -2.94886</pose>
          <velocity>1e-06 -6e-06 1.4e-05 0.000123 2.5e-05 -1e-06</velocity>
          <acceleration>-1e-06 -1e-06 0 2.6e-05 -0.016449 0</acceleration>
          <wrench>0 0 0 0 -0 0</wrench>
        </link>
        <link name='right_rear_wheel'>
          <pose frame=''>-8e-06 -0.100003 0.049999 1.5708 -0.000173 -3e-06</pose>
          <velocity>1e-06 0 1.3e-05 2e-06 1.9e-05 1e-06</velocity>
          <acceleration>-1e-06 0 0 -4e-06 -0.027699 -2e-06</acceleration>
          <wrench>0 0 0 0 -0 0</wrench>
        </link>
        <link name='right_steering_hinge'>
          <pose frame=''>0.324992 -0.100004 0.049996 1.93321 1.57076 1.93358</pose>
          <velocity>1e-06 3e-06 1.6e-05 -9.7e-05 -1.2e-05 5e-06</velocity>
          <acceleration>-1e-06 -2e-06 -1e-06 3e-06 1e-06 1e-06</acceleration>
          <wrench>0 0 0 0 -0 0</wrench>
        </link>
      </model>
      <light name='Light 1'>
        <pose frame=''>0 0 15 0 -0 0</pose>
      </light>
      <light name='sun'>
        <pose frame=''>0 0 10 0 -0 0</pose>
      </light>
    </state>
  </world>
</sdf>
